Workbook

Sheet Жами тола
A1: ПТМ | B1: Нави | D1: Марка | E1: Кип сони | F1: Брутто | G1: Нетто | H1: той сони | I1: нав | J1: синф | K1: Нетто
A2: Корхона олди | B2: Бухоро 102 | C2: кул терим | D2: 201 | E2: ='201'!B56 -> 220 | F2: ='201'!E56 -> 41411.7 | G2: ='201'!J56 -> 40949.7 | H2: 174 | I2: 1 | J2: яхши | K2: 32346.8
H3: 34 | I3: 1 | J3: ўрта | K3: 6427
H4: 12 | I4: 1 | J4: оддий | K4: 2175.9
A5: Корхона олди | B5: С01 | C5: кул терим | D5: 202 | E5: =+'202'!B56+'202'!M56 -> 220 | F5: =+'202'!E56+'202'!P56 -> 43285.2 | G5: =+'202'!J56+'202'!U56 -> 42813.8 | H5: =Сертификат!B26 -> 183 | I5: 1 | J5: ўрта | K5: =Сертификат!D26 -> 35351
H6: =Сертификат!B27 -> 37 | I6: 1 | J6: оддий | K6: =Сертификат!D27 -> 7462.8
A7: Корхона олди | B7: Бухоро 102 | C7: кул терим | D7: 203 | E7: ='203'!B56 -> 220 | F7: ='203'!E56 -> 42672 | G7: =+'203'!J56 -> 42210 | H7: 158 | I7: 1 | J7: яхши | K7: 30330.3
H8: 62 | I8: 1 | J8: ўрта | K8: 11879.7
A9: Корхона олди | B9: Бухоро 102 | C9: кул терим | D9: 204 | E9: ='204'!B56 -> 220 | F9: ='204'!E56 -> 42176.6 | G9: ='204'!J56 -> 41714.6 | H9: =Сертификат!B58 -> 109 | I9: 1 | J9: яхши | K9: =Сертификат!D58 -> 20515
H10: =Сертификат!B59 -> 111 | I10: 1 | J10: ўрта | K10: =Сертификат!D59 -> 21199.6
A11: Корхона олди | B11: Бухоро 102 | C11: кул терим | D11: 205 | E11: ='205'!B56 -> 220 | F11: ='205'!E56 -> 44500.7 | G11: ='205'!J56 -> 44038.7 | H11: =Сертификат!B74 -> 111 | I11: 1 | J11: ўрта | K11: =Сертификат!D74 -> 21835.3
H12: =Сертификат!B75 -> 109 | I12: 1 | J12: оддий | K12: =Сертификат!D75 -> 22203.4
A13: Корхона олди | B13: Хоразм 127 | C13: кул терим | D13: 206 | E13: ='206'!B56 -> 64 | F13: ='206'!E56 -> 13549.6 | G13: ='206'!J56 -> 13415.2 | H13: =Сертификат!B90 -> 64 | I13: 1 | J13: оддий | K13: =Сертификат!D90 -> 13415.2
A14: Корхона олди | B14: Бухоро 102 | C14: кул терим | D14: 207 | E14: =+'207'!B56+'207'!M56 -> 220 | F14: =+'207'!E56+'207'!P56 -> 44254.1 | G14: =+'207'!J56+'207'!U56 -> 43770.2 | H14: =Сертификат!B105 -> 73 | I14: 1 | J14: ўрта | K14: =Сертификат!D105 -> 14425.3
H15: =Сертификат!B106 -> 147 | I15: 1 | J15: оддий | K15: =Сертификат!D106 -> 29344.9
A16: Корхона олди | B16: С01 | C16: кул терим | D16: 208 | E16: ='208'!B56 -> 87 | F16: ='208'!E56 -> 17071.4 | G16: ='208'!J56 -> 16880 | H16: =Сертификат!B121 -> 61 | I16: 1 | J16: ифлос | K16: =Сертификат!D121 -> 11844.4
H17: 26 | I17: 1 | J17: ўрта | K17: 5035.6
A18: Корхона олди | B18: Бухоро 102 | C18: кул терим | D18: 209 | E18: ='209'!B56 -> 220 | F18: ='209'!E56 -> 44133.1 | G18: ='209'!J56 -> 43649.1 | H18: =Сертификат!B138 -> 101 | I18: 1 | J18: яхши | K18: =Сертификат!D138 -> 20010.7
H19: =Сертификат!B139 -> 119 | I19: 1 | J19: ўрта | K19: =Сертификат!D139 -> 23638.4
A20: Корхона олди | B20: Бухоро 102 | C20: кул терим | D20: 210 | E20: ='210'!B56 -> 220 | F20: ='210'!E56 -> 44218.4 | G20: ='210'!J56 -> 43734.4 | H20: 109 | I20: 1 | J20: яхши | K20: 21598.6
H21: 111 | I21: 1 | J21: ўрта | K21: 22135.8
A22: Корхона олди | B22: Бухоро 102 | C22: кул терим | D22: 211 | E22: ='211'!B56 -> 220 | F22: ='211'!E56 -> 44380.9 | G22: ='211'!J56 -> 43896.9 | H22: 170 | I22: 1 | J22: яхши | K22: 33893.2
H23: 50 | I23: 1 | J23: ўрта | K23: 10003.7
A24: Корхона олди | B24: Бухоро 102 | C24: кул терим | D24: 212 | E24: ='212'!B56 -> 220 | F24: ='212'!E56 -> 43980 | G24: ='212'!J56 -> 43496 | H24: =Сертификат!B189 -> 89 | I24: 1 | J24: яхши | K24: =Сертификат!D189 -> 17555.8
H25: =Сертификат!B190 -> 131 | I25: 1 | J25: ўрта | K25: =Сертификат!D190 -> 25940.2
A26: Корхона олди | B26: Бухоро 102 | C26: кул терим | D26: 213 | E26: ='213'!B56 -> 220 | F26: ='213'!E56 -> 44149.8 | G26: ='213'!J56 -> 43665.8 | H26: =Сертификат!B206 -> 149 | I26: 1 | J26: яхши | K26: =Сертификат!D206 -> 29579
H27: =Сертификат!B207 -> 71 | I27: 1 | J27: ўрта | K27: =Сертификат!D207 -> 14086.8
A28: Корхона олди | B28: Бухоро 102 | C28: кул терим | D28: 214 | E28: ='214'!B56 -> 220 | F28: ='214'!E56 -> 44111 | G28: ='214'!J56 -> 43627 | H28: =Сертификат!B222 -> 114 | I28: 1 | J28: яхши | K28: =Сертификат!D222 -> 22560.1
H29: =Сертификат!B223 -> 106 | I29: 1 | J29: ўрта | K29: =Сертификат!D223 -> 21066.9
A30: Корхона олди | B30: Бухоро 102 | C30: кул терим | D30: 215 | E30: ='215'!B56 -> 220 | F30: ='215'!E56 -> 44536.6 | G30: ='215'!J56 -> 44052.6 | H30: =Сертификат!B238 -> 156 | I30: 1 | J30: яхши | K30: =Сертификат!D238 -> 31288.6
H31: =Сертификат!B239 -> 64 | I31: 1 | J31: ўрта | K31: =Сертификат!D239 -> 12764
A32: Корхона олди | B32: Бухоро 102 | C32: кул терим | D32: 216 | E32: ='216'!B56 -> 220 | F32: ='216'!E56 -> 44387.3 | G32: ='216'!J56 -> 43903.3 | H32: =Сертификат!B255 -> 36 | I32: 1 | J32: яхши | K32: =Сертификат!D255 -> 7094.2
H33: =Сертификат!B256 -> 129 | I33: 1 | J33: ўрта | K33: =Сертификат!D256 -> 25795.4
H34: =Сертификат!B257 -> 55 | I34: 1 | J34: оддий | K34: =Сертификат!D257 -> 11013.7
A35: Корхона олди | B35: Бухоро 102 | C35: кул терим | D35: 217 | E35: ='217'!B56 -> 220 | F35: ='217'!E56 -> 44811.8 | G35: ='217'!J56 -> 44327.8 | H35: =Сертификат!B273 -> 119 | I35: 1 | J35: яхши | K35: =Сертификат!D273 -> 23749.2
H36: =Сертификат!B274 -> 101 | I36: 1 | J36: ўрта | K36: =Сертификат!D274 -> 20578.6
A37: Корхона олди | B37: Бухоро 102 | C37: кул терим | D37: 218 | E37: ='218'!B56 -> 220 | F37: ='218'!E56 -> 44086.7 | G37: ='218'!J56 -> 43602.7 | H37: =Сертификат!B289 -> 85 | I37: 1 | J37: яхши | K37: =Сертификат!D289 -> 16841.6
H38: =Сертификат!B290 -> 135 | I38: 1 | J38: ўрта | K38: =Сертификат!D290 -> 26761.1
A39: Корхона олди | B39: Бухоро 102 | C39: кул терим | D39: 219 | E39: ='219'!B56 -> 220 | F39: ='219'!E56 -> 44080 | G39: ='219'!J56 -> 43596 | H39: =Сертификат!B307 -> 60 | I39: 1 | J39: яхши | K39: =Сертификат!D307 -> 11676
H40: =Сертификат!B308 -> 160 | I40: 1 | J40: ўрта | K40: =Сертификат!D308 -> 31920
...

Sheet Сертификат
A1: СИФАТ СЕРТИФИКАТИ
A3: Лаборатория: "Navbahor Tekstil" МЧЖ га қарашли пахта заводи.
A4: Махсулот номи: Пахта толаси.
A6: Марка: № 201
A7: Завод | B7: Той сони | C7: Брутто (кг) | D7: Нетто (кг) | E7: Тахлил натижалари | K7: Ифлослик | L7: Намлик
E8: Тип | F8: Нав | G8: Синф | H8: Пишиб етилганлик коэффициенти | I8: Штапел узунлиги коди | J8: Микронейр
A9: 211 | B9: ='201'!X56 -> 174 | C9: ='201'!AA56 -> 32712.2 | D9: ='201'!AF56 -> 32346.8 | E9: 4 | F9: 1 | G9: яхши | H9: 1.8 | I9: 36 | J9: 4.5 | K9: 2.5 | L9: 5
A10: 211 | B10: ='201'!AI56 -> 34 | C10: ='201'!AL56 -> 6498.4 | D10: ='201'!AQ56 -> 6427 | E10: 4 | F10: 1 | G10: ўрта | H10: 1.8 | I10: 36 | J10: 4.5 | K10: 3 | L10: 5
A11: 211 | B11: ='201'!M56 -> 12 | C11: ='201'!P56 -> 2201.1 | D11: ='201'!U56 -> 2175.9 | E11: 4 | F11: 1 | G11: оддий | H11: 1.8 | I11: 36 | J11: 4.5 | K11: 4 | L11: 5
A12: Всего: | B12: =SUM(B9:B11) -> 220 | C12: =SUM(C9:C11) -> 41411.7 | D12: =SUM(D9:D11) -> 40949.7
A14: "Navbahor Tekstil" МЧЖ
A15: хлопзавод при ООО "Navbahor Tekstil" | B15: лаборатория мудири : | G15: ____________ | I15: С.С.Мухаммадиев
A18: СИФАТ СЕРТИФИКАТИ
A20: Лаборатория: "Navbahor Tekstil" МЧЖ га қарашли пахта заводи.
A21: Махсулот номи: Пахта толаси.
A23: Марка: № 202
A24: Завод | B24: Той сони | C24: Брутто (кг) | D24: Нетто (кг) | E24: Тахлил натижалари | K24: Ифлослик | L24: Намлик
E25: Тип | F25: Нав | G25: Синф | H25: Пишиб етилганлик коэффициенти | I25: Штапел узунлиги коди | J25: Микронейр
A26: 211 | B26: ='202'!X56+'202'!AI56 -> 183 | C26: ='202'!AA56+'202'!AL56 -> 35741 | D26: ='202'!AF56+'202'!AQ56 -> 35351 | E26: 4 | F26: 1 | G26: урта | H26: 1.8 | I26: 37 | J26: 4.5 | K26: 3 | L26: 5
A27: 211 | B27: ='202'!AT56 -> 37 | C27: ='202'!AW56 -> 7544.2 | D27: ='202'!BB56 -> 7462.8 | E27: 4 | F27: 1 | G27: оддий | H27: 1.8 | I27: 37 | J27: 4.5 | K27: 4 | L27: 5
A28: Всего: | B28: =SUM(B26:B27) -> 220 | C28: =SUM(C26:C27) -> 43285.2 | D28: =SUM(D26:D27) -> 42813.8
A30: "Navbahor Tekstil" МЧЖ
A31: хлопзавод при ООО "Navbahor Tekstil" | B31: лаборатория мудири : | G31: ____________ | I31: С.С.Мухаммадиев
A34: СИФАТ СЕРТИФИКАТИ
A36: Лаборатория: "Navbahor Tekstil" МЧЖ га қарашли пахта заводи.
A37: Махсулот номи: Пахта толаси.
A39: Марка: № 203
A40: Завод | B40: Той сони | C40: Брутто (кг) | D40: Нетто (кг) | E40: Тахлил натижалари | K40: Ифлослик | L40: Намлик
E41: Тип | F41: Нав | G41: Синф | H41: Пишиб етилганлик коэффициенти | I41: Штапел узунлиги коди | J41: Микронейр
A42: 211 | B42: ='203'!M56 -> 158 | C42: ='203'!P56 -> 30662.1 | D42: ='203'!U56 -> 30330.3 | E42: 4 | F42: 1 | G42: яхши | H42: 1.8 | I42: 36 | J42: 4.5 | K42: 2.5 | L42: 5
A43: 211 | B43: ='203'!X56 -> 62 | C43: ='203'!AA56 -> 12009.9 | D43: ='203'!AF56 -> 11879.7 | E43: 4 | F43: 1 | G43: ўрта | H43: 1.8 | I43: 36 | J43: 4.5 | K43: 3 | L43: 5
A44: Всего: | B44: =SUM(B42:B43) -> 220 | C44: =SUM(C42:C43) -> 42672 | D44: =SUM(D42:D43) -> 42210
A46: "Navbahor Tekstil" МЧЖ
A47: хлопзавод при ООО "Navbahor Tekstil" | B47: лаборатория мудири : | G47: ____________ | I47: С.С.Мухаммадиев
A50: СИФАТ СЕРТИФИКАТИ
A52: Лаборатория: "Navbahor Tekstil" МЧЖ га қарашли пахта заводи.
A53: Махсулот номи: Пахта толаси.
A55: Марка: № 204
A56: Завод | B56: Той сони | C56: Брутто (кг) | D56: Нетто (кг) | E56: Тахлил натижалари | K56: Ифлослик | L56: Намлик
E57: Тип | F57: Нав | G57: Синф | H57: Пишиб етилганлик коэффициенти | I57: Штапел узунлиги коди | J57: Микронейр
...

Sheet 240
A1: Акт покипного отвеса
A2: Лаборатория: хлопзавод при ООО "Navbahor Tekstil"
A3: Марка № | I3: Корхона олди
I4: Жами
A5: № | B5: Масса | C5: № | D5: Масса | E5: № | F5: Масса | G5: № | H5: Масса | I5: № | J5: Масса
A6: 1 | C6: 50 | E6: 99 | G6: 148 | I6: 197
A7: 2 | C7: 51 | E7: 100 | G7: 149 | I7: 198
A8: 3 | C8: 52 | E8: =+E7+1 -> 101 | G8: 150 | I8: 199
A9: 4 | C9: 53 | E9: =+E8+1 -> 102 | G9: 151 | I9: 200
A10: 5 | C10: 54 | E10: =+E9+1 -> 103 | G10: 152 | I10: 201
A11: 6 | C11: 55 | E11: =+E10+1 -> 104 | G11: 153 | I11: 202
A12: 7 | C12: 56 | E12: =+E11+1 -> 105 | G12: 154 | I12: 203
A13: 8 | C13: 57 | E13: =+E12+1 -> 106 | G13: 155 | I13: 204
A14: 9 | C14: 58 | E14: =+E13+1 -> 107 | G14: 156 | I14: 205
A15: 10 | C15: 59 | E15: =+E14+1 -> 108 | G15: 157 | I15: 206
A16: 11 | C16: 60 | E16: =+E15+1 -> 109 | G16: 158 | I16: 207
A17: 12 | C17: 61 | E17: =+E16+1 -> 110 | G17: 159 | I17: 208
A18: 13 | C18: 62 | E18: =+E17+1 -> 111 | G18: 160 | I18: 209
A19: 14 | C19: 63 | E19: =+E18+1 -> 112 | G19: 161 | I19: 210
... A29: 24 | C29: 73 | E29: =+E28+1 -> 122 | G29: 171 | I29: 220
A30: 25 | C30: 74 | E30: =+E29+1 -> 123 | G30: 172
A31: 26 | C31: 75 | E31: =+E30+1 -> 124 | G31: 173
A32: 27 | C32: 76 | E32: =+E31+1 -> 125 | G32: 174
A33: 28 | C33: 77 | E33: =+E32+1 -> 126 | G33: 175
A34: 29 | C34: 78 | E34: =+E33+1 -> 127 | G34: 176
A35: 30 | C35: 79 | E35: =+E34+1 -> 128 | G35: 177
A36: 31 | C36: 80 | E36: =+E35+1 -> 129 | G36: 178
A37: 32 | C37: 81 | E37: =+E36+1 -> 130 | G37: 179
A38: 33 | C38: 82 | E38: =+E37+1 -> 131 | G38: 180
A39: 34 | C39: 83 | E39: =+E38+1 -> 132 | G39: 181
A40: 35 | C40: 84 | E40: =+E39+1 -> 133 | G40: 182
A41: 36 | C41: 85 | E41: =+E40+1 -> 134 | G41: 183
... A54: 49 | C54: 98 | E54: =+E53+1 -> 147 | G54: 196
B55: =SUM(B6:B54) -> 0 | D55: =SUM(D6:D54) -> 0 | F55: =SUM(F6:F54) -> 0 | H55: =SUM(H6:H54) -> 0 | J55: =SUM(J6:J54) -> 0
A56: Итого кип | B56: =COUNT(B6:B54,D6:D54,F6:F54,H6:H54,J6:J54) -> 0 | C56: Масса брутто | E56: =B55+D55+F55+H55+J55 -> 0 | F56: Тары | G56: =B56*2.2 -> 0 | H56: Масса нетто | J56: =E56-G56 -> 0
A57: Лаборант:
F59: Тара | G59: 2.2

Sheet 239
A1: Акт покипного отвеса
A2: Лаборатория: хлопзавод при ООО "Navbahor Tekstil"
A3: Марка № | I3: Корхона олди
I4: Жами
A5: № | B5: Масса | C5: № | D5: Масса | E5: № | F5: Масса | G5: № | H5: Масса | I5: № | J5: Масса
A6: 1 | C6: 50 | E6: 99 | G6: 148 | I6: 197
A7: 2 | C7: 51 | E7: 100 | G7: 149 | I7: 198
A8: 3 | C8: 52 | E8: =+E7+1 -> 101 | G8: 150 | I8: 199
A9: 4 | C9: 53 | E9: =+E8+1 -> 102 | G9: 151 | I9: 200
A10: 5 | C10: 54 | E10: =+E9+1 -> 103 | G10: 152 | I10: 201
A11: 6 | C11: 55 | E11: =+E10+1 -> 104 | G11: 153 | I11: 202
A12: 7 | C12: 56 | E12: =+E11+1 -> 105 | G12: 154 | I12: 203
A13: 8 | C13: 57 | E13: =+E12+1 -> 106 | G13: 155 | I13: 204
A14: 9 | C14: 58 | E14: =+E13+1 -> 107 | G14: 156 | I14: 205
A15: 10 | C15: 59 | E15: =+E14+1 -> 108 | G15: 157 | I15: 206
A16: 11 | C16: 60 | E16: =+E15+1 -> 109 | G16: 158 | I16: 207
A17: 12 | C17: 61 | E17: =+E16+1 -> 110 | G17: 159 | I17: 208
A18: 13 | C18: 62 | E18: =+E17+1 -> 111 | G18: 160 | I18: 209
A19: 14 | C19: 63 | E19: =+E18+1 -> 112 | G19: 161 | I19: 210
... A29: 24 | C29: 73 | E29: =+E28+1 -> 122 | G29: 171 | I29: 220
A30: 25 | C30: 74 | E30: =+E29+1 -> 123 | G30: 172
A31: 26 | C31: 75 | E31: =+E30+1 -> 124 | G31: 173
A32: 27 | C32: 76 | E32: =+E31+1 -> 125 | G32: 174
A33: 28 | C33: 77 | E33: =+E32+1 -> 126 | G33: 175
A34: 29 | C34: 78 | E34: =+E33+1 -> 127 | G34: 176
A35: 30 | C35: 79 | E35: =+E34+1 -> 128 | G35: 177
A36: 31 | C36: 80 | E36: =+E35+1 -> 129 | G36: 178
A37: 32 | C37: 81 | E37: =+E36+1 -> 130 | G37: 179
A38: 33 | C38: 82 | E38: =+E37+1 -> 131 | G38: 180
A39: 34 | C39: 83 | E39: =+E38+1 -> 132 | G39: 181
A40: 35 | C40: 84 | E40: =+E39+1 -> 133 | G40: 182
A41: 36 | C41: 85 | E41: =+E40+1 -> 134 | G41: 183
... A54: 49 | C54: 98 | E54: =+E53+1 -> 147 | G54: 196
B55: =SUM(B6:B54) -> 0 | D55: =SUM(D6:D54) -> 0 | F55: =SUM(F6:F54) -> 0 | H55: =SUM(H6:H54) -> 0 | J55: =SUM(J6:J54) -> 0
A56: Итого кип | B56: =COUNT(B6:B54,D6:D54,F6:F54,H6:H54,J6:J54) -> 0 | C56: Масса брутто | E56: =B55+D55+F55+H55+J55 -> 0 | F56: Тары | G56: =B56*2.2 -> 0 | H56: Масса нетто | J56: =E56-G56 -> 0
A57: Лаборант:
F59: Тара | G59: 2.2

Sheet 238
A1: Акт покипного отвеса
A2: Лаборатория: хлопзавод при ООО "Navbahor Tekstil"
A3: Марка № | I3: Корхона олди
I4: Жами
A5: № | B5: Масса | C5: № | D5: Масса | E5: № | F5: Масса | G5: № | H5: Масса | I5: № | J5: Масса
A6: 1 | C6: 50 | E6: 99 | G6: 148 | I6: 197
A7: 2 | C7: 51 | E7: 100 | G7: 149 | I7: 198
A8: 3 | C8: 52 | E8: =+E7+1 -> 101 | G8: 150 | I8: 199
A9: 4 | C9: 53 | E9: =+E8+1 -> 102 | G9: 151 | I9: 200
A10: 5 | C10: 54 | E10: =+E9+1 -> 103 | G10: 152 | I10: 201
A11: 6 | C11: 55 | E11: =+E10+1 -> 104 | G11: 153 | I11: 202
A12: 7 | C12: 56 | E12: =+E11+1 -> 105 | G12: 154 | I12: 203
A13: 8 | C13: 57 | E13: =+E12+1 -> 106 | G13: 155 | I13: 204
A14: 9 | C14: 58 | E14: =+E13+1 -> 107 | G14: 156 | I14: 205
A15: 10 | C15: 59 | E15: =+E14+1 -> 108 | G15: 157 | I15: 206
A16: 11 | C16: 60 | E16: =+E15+1 -> 109 | G16: 158 | I16: 207
A17: 12 | C17: 61 | E17: =+E16+1 -> 110 | G17: 159 | I17: 208
A18: 13 | C18: 62 | E18: =+E17+1 -> 111 | G18: 160 | I18: 209
A19: 14 | C19: 63 | E19: =+E18+1 -> 112 | G19: 161 | I19: 210
... A29: 24 | C29: 73 | E29: =+E28+1 -> 122 | G29: 171 | I29: 220
A30: 25 | C30: 74 | E30: =+E29+1 -> 123 | G30: 172
A31: 26 | C31: 75 | E31: =+E30+1 -> 124 | G31: 173
A32: 27 | C32: 76 | E32: =+E31+1 -> 125 | G32: 174
A33: 28 | C33: 77 | E33: =+E32+1 -> 126 | G33: 175
A34: 29 | C34: 78 | E34: =+E33+1 -> 127 | G34: 176
A35: 30 | C35: 79 | E35: =+E34+1 -> 128 | G35: 177
A36: 31 | C36: 80 | E36: =+E35+1 -> 129 | G36: 178
A37: 32 | C37: 81 | E37: =+E36+1 -> 130 | G37: 179
A38: 33 | C38: 82 | E38: =+E37+1 -> 131 | G38: 180
A39: 34 | C39: 83 | E39: =+E38+1 -> 132 | G39: 181
A40: 35 | C40: 84 | E40: =+E39+1 -> 133 | G40: 182
A41: 36 | C41: 85 | E41: =+E40+1 -> 134 | G41: 183
... A54: 49 | C54: 98 | E54: =+E53+1 -> 147 | G54: 196
B55: =SUM(B6:B54) -> 0 | D55: =SUM(D6:D54) -> 0 | F55: =SUM(F6:F54) -> 0 | H55: =SUM(H6:H54) -> 0 | J55: =SUM(J6:J54) -> 0
A56: Итого кип | B56: =COUNT(B6:B54,D6:D54,F6:F54,H6:H54,J6:J54) -> 0 | C56: Масса брутто | E56: =B55+D55+F55+H55+J55 -> 0 | F56: Тары | G56: =B56*2.2 -> 0 | H56: Масса нетто | J56: =E56-G56 -> 0
A57: Лаборант:
F59: Тара | G59: 2.2

Sheet 237
A1: Акт покипного отвеса
A2: Лаборатория: хлопзавод при ООО "Navbahor Tekstil"
A3: Марка № | I3: Корхона олди
I4: Жами
A5: № | B5: Масса | C5: № | D5: Масса | E5: № | F5: Масса | G5: № | H5: Масса | I5: № | J5: Масса
A6: 1 | C6: 50 | E6: 99 | G6: 148 | I6: 197
A7: 2 | C7: 51 | E7: 100 | G7: 149 | I7: 198
A8: 3 | C8: 52 | E8: =+E7+1 -> 101 | G8: 150 | I8: 199
A9: 4 | C9: 53 | E9: =+E8+1 -> 102 | G9: 151 | I9: 200
A10: 5 | C10: 54 | E10: =+E9+1 -> 103 | G10: 152 | I10: 201
A11: 6 | C11: 55 | E11: =+E10+1 -> 104 | G11: 153 | I11: 202
A12: 7 | C12: 56 | E12: =+E11+1 -> 105 | G12: 154 | I12: 203
A13: 8 | C13: 57 | E13: =+E12+1 -> 106 | G13: 155 | I13: 204
A14: 9 | C14: 58 | E14: =+E13+1 -> 107 | G14: 156 | I14: 205
A15: 10 | C15: 59 | E15: =+E14+1 -> 108 | G15: 157 | I15: 206
A16: 11 | C16: 60 | E16: =+E15+1 -> 109 | G16: 158 | I16: 207
A17: 12 | C17: 61 | E17: =+E16+1 -> 110 | G17: 159 | I17: 208
A18: 13 | C18: 62 | E18: =+E17+1 -> 111 | G18: 160 | I18: 209
A19: 14 | C19: 63 | E19: =+E18+1 -> 112 | G19: 161 | I19: 210
... A29: 24 | C29: 73 | E29: =+E28+1 -> 122 | G29: 171 | I29: 220
A30: 25 | C30: 74 | E30: =+E29+1 -> 123 | G30: 172
A31: 26 | C31: 75 | E31: =+E30+1 -> 124 | G31: 173
A32: 27 | C32: 76 | E32: =+E31+1 -> 125 | G32: 174
A33: 28 | C33: 77 | E33: =+E32+1 -> 126 | G33: 175
A34: 29 | C34: 78 | E34: =+E33+1 -> 127 | G34: 176
A35: 30 | C35: 79 | E35: =+E34+1 -> 128 | G35: 177
A36: 31 | C36: 80 | E36: =+E35+1 -> 129 | G36: 178
A37: 32 | C37: 81 | E37: =+E36+1 -> 130 | G37: 179
A38: 33 | C38: 82 | E38: =+E37+1 -> 131 | G38: 180
A39: 34 | C39: 83 | E39: =+E38+1 -> 132 | G39: 181
A40: 35 | C40: 84 | E40: =+E39+1 -> 133 | G40: 182
A41: 36 | C41: 85 | E41: =+E40+1 -> 134 | G41: 183
... A54: 49 | C54: 98 | E54: =+E53+1 -> 147 | G54: 196
B55: =SUM(B6:B54) -> 0 | D55: =SUM(D6:D54) -> 0 | F55: =SUM(F6:F54) -> 0 | H55: =SUM(H6:H54) -> 0 | J55: =SUM(J6:J54) -> 0
A56: Итого кип | B56: =COUNT(B6:B54,D6:D54,F6:F54,H6:H54,J6:J54) -> 0 | C56: Масса брутто | E56: =B55+D55+F55+H55+J55 -> 0 | F56: Тары | G56: =B56*2.2 -> 0 | H56: Масса нетто | J56: =E56-G56 -> 0
A57: Лаборант:
F59: Тара | G59: 2.2

Sheet 236
A1: Акт покипного отвеса
A2: Лаборатория: хлопзавод при ООО "Navbahor Tekstil"
A3: Марка № | I3: Корхона олди
I4: Жами
A5: № | B5: Масса | C5: № | D5: Масса | E5: № | F5: Масса | G5: № | H5: Масса | I5: № | J5: Масса
A6: 1 | C6: 50 | E6: 99 | G6: 148 | I6: 197
A7: 2 | C7: 51 | E7: 100 | G7: 149 | I7: 198
A8: 3 | C8: 52 | E8: =+E7+1 -> 101 | G8: 150 | I8: 199
A9: 4 | C9: 53 | E9: =+E8+1 -> 102 | G9: 151 | I9: 200
A10: 5 | C10: 54 | E10: =+E9+1 -> 103 | G10: 152 | I10: 201
A11: 6 | C11: 55 | E11: =+E10+1 -> 104 | G11: 153 | I11: 202
A12: 7 | C12: 56 | E12: =+E11+1 -> 105 | G12: 154 | I12: 203
A13: 8 | C13: 57 | E13: =+E12+1 -> 106 | G13: 155 | I13: 204
A14: 9 | C14: 58 | E14: =+E13+1 -> 107 | G14: 156 | I14: 205
A15: 10 | C15: 59 | E15: =+E14+1 -> 108 | G15: 157 | I15: 206
A16: 11 | C16: 60 | E16: =+E15+1 -> 109 | G16: 158 | I16: 207
A17: 12 | C17: 61 | E17: =+E16+1 -> 110 | G17: 159 | I17: 208
A18: 13 | C18: 62 | E18: =+E17+1 -> 111 | G18: 160 | I18: 209
A19: 14 | C19: 63 | E19: =+E18+1 -> 112 | G19: 161 | I19: 210
... A29: 24 | C29: 73 | E29: =+E28+1 -> 122 | G29: 171 | I29: 220
A30: 25 | C30: 74 | E30: =+E29+1 -> 123 | G30: 172
A31: 26 | C31: 75 | E31: =+E30+1 -> 124 | G31: 173
A32: 27 | C32: 76 | E32: =+E31+1 -> 125 | G32: 174
A33: 28 | C33: 77 | E33: =+E32+1 -> 126 | G33: 175
A34: 29 | C34: 78 | E34: =+E33+1 -> 127 | G34: 176
A35: 30 | C35: 79 | E35: =+E34+1 -> 128 | G35: 177
A36: 31 | C36: 80 | E36: =+E35+1 -> 129 | G36: 178
A37: 32 | C37: 81 | E37: =+E36+1 -> 130 | G37: 179
A38: 33 | C38: 82 | E38: =+E37+1 -> 131 | G38: 180
A39: 34 | C39: 83 | E39: =+E38+1 -> 132 | G39: 181
A40: 35 | C40: 84 | E40: =+E39+1 -> 133 | G40: 182
A41: 36 | C41: 85 | E41: =+E40+1 -> 134 | G41: 183
... A54: 49 | C54: 98 | E54: =+E53+1 -> 147 | G54: 196
B55: =SUM(B6:B54) -> 0 | D55: =SUM(D6:D54) -> 0 | F55: =SUM(F6:F54) -> 0 | H55: =SUM(H6:H54) -> 0 | J55: =SUM(J6:J54) -> 0
A56: Итого кип | B56: =COUNT(B6:B54,D6:D54,F6:F54,H6:H54,J6:J54) -> 0 | C56: Масса брутто | E56: =B55+D55+F55+H55+J55 -> 0 | F56: Тары | G56: =B56*2.2 -> 0 | H56: Масса нетто | J56: =E56-G56 -> 0
A57: Лаборант:
F59: Тара | G59: 2.2

Sheet 235
A1: Акт покипного отвеса
A2: Лаборатория: хлопзавод при ООО "Navbahor Tekstil"
A3: Марка № | B3: 235 | I3: Корхона олди
I4: Жами
A5: № | B5: Масса | C5: № | D5: Масса | E5: № | F5: Масса | G5: № | H5: Масса | I5: № | J5: Масса
A6: 1 | B6: 189.6 | C6: 50 | D6: 207.5 | E6: 99 | F6: 199.7 | G6: 148 | H6: 191.2 | I6: 197
A7: 2 | B7: 204.8 | C7: 51 | D7: 207.8 | E7: 100 | F7: 199.1 | G7: 149 | H7: 211.9 | I7: 198
A8: 3 | B8: 200.4 | C8: 52 | D8: 212.7 | E8: =+E7+1 -> 101 | F8: 195.7 | G8: 150 | H8: 180.4 | I8: 199
A9: 4 | B9: 205.2 | C9: 53 | D9: 208.1 | E9: =+E8+1 -> 102 | F9: 203.8 | G9: 151 | H9: 213.9 | I9: 200
A10: 5 | B10: 200.7 | C10: 54 | D10: 208.7 | E10: =+E9+1 -> 103 | F10: 187.9 | G10: 152 | H10: 174.2 | I10: 201
A11: 6 | B11: 206 | C11: 55 | D11: 209.5 | E11: =+E10+1 -> 104 | F11: 212 | G11: 153 | H11: 216.4 | I11: 202
A12: 7 | B12: 203.3 | C12: 56 | D12: 209.8 | E12: =+E11+1 -> 105 | F12: 192.5 | G12: 154 | I12: 203
A13: 8 | B13: 205.5 | C13: 57 | D13: 210.5 | E13: =+E12+1 -> 106 | F13: 207.8 | G13: 155 | I13: 204
A14: 9 | B14: 202.6 | C14: 58 | D14: 206.4 | E14: =+E13+1 -> 107 | F14: 195 | G14: 156 | I14: 205
A15: 10 | B15: 199.7 | C15: 59 | D15: 209.1 | E15: =+E14+1 -> 108 | F15: 178.2 | G15: 157 | I15: 206
A16: 11 | B16: 200.2 | C16: 60 | D16: 207.4 | E16: =+E15+1 -> 109 | F16: 212.5 | G16: 158 | I16: 207
A17: 12 | B17: 205.4 | C17: 61 | D17: 209.6 | E17: =+E16+1 -> 110 | F17: 190.2 | G17: 159 | I17: 208
A18: 13 | B18: 198.3 | C18: 62 | D18: 210 | E18: =+E17+1 -> 111 | F18: 206.8 | G18: 160 | I18: 209
A19: 14 | B19: 188.6 | C19: 63 | D19: 204.7 | E19: =+E18+1 -> 112 | F19: 188.5 | G19: 161 | I19: 210
A20: 15 | B20: 199 | C20: 64 | D20: 203.4 | E20: =+E19+1 -> 113 | F20: 209.5 | G20: 162 | I20: 211
A21: 16 | B21: 201.8 | C21: 65 | D21: 210.7 | E21: =+E20+1 -> 114 | F21: 209.2 | G21: 163 | I21: 212
A22: 17 | B22: 194.4 | C22: 66 | D22: 201.8 | E22: =+E21+1 -> 115 | F22: 172 | G22: 164 | I22: 213
A23: 18 | B23: 208.3 | C23: 67 | D23: 204.6 | E23: =+E22+1 -> 116 | F23: 186.7 | G23: 165 | I23: 214
... A29: 24 | B29: 200.7 | C29: 73 | D29: 205.3 | E29: =+E28+1 -> 122 | F29: 208.4 | G29: 171 | I29: 220
A30: 25 | B30: 203.5 | C30: 74 | D30: 206.9 | E30: =+E29+1 -> 123 | F30: 179.1 | G30: 172
A31: 26 | B31: 195.7 | C31: 75 | D31: 200.6 | E31: =+E30+1 -> 124 | F31: 160.6 | G31: 173
A32: 27 | B32: 202.3 | C32: 76 | D32: 204 | E32: =+E31+1 -> 125 | F32: 208.2 | G32: 174
A33: 28 | B33: 209.8 | C33: 77 | D33: 208.6 | E33: =+E32+1 -> 126 | F33: 198.7 | G33: 175
A34: 29 | B34: 207.7 | C34: 78 | D34: 205.6 | E34: =+E33+1 -> 127 | F34: 207.1 | G34: 176
A35: 30 | B35: 205.2 | C35: 79 | D35: 203.6 | E35: =+E34+1 -> 128 | F35: 206.9 | G35: 177
A36: 31 | B36: 205.7 | C36: 80 | D36: 203 | E36: =+E35+1 -> 129 | F36: 179.9 | G36: 178
A37: 32 | B37: 197.7 | C37: 81 | D37: 205.2 | E37: =+E36+1 -> 130 | F37: 210.1 | G37: 179
A38: 33 | B38: 202.6 | C38: 82 | D38: 206.5 | E38: =+E37+1 -> 131 | F38: 185.6 | G38: 180
A39: 34 | B39: 205.8 | C39: 83 | D39: 177.8 | E39: =+E38+1 -> 132 | F39: 209.6 | G39: 181
A40: 35 | B40: 198.3 | C40: 84 | D40: 195.8 | E40: =+E39+1 -> 133 | F40: 206.8 | G40: 182
A41: 36 | B41: 199.2 | C41: 85 | D41: 158.1 | E41: =+E40+1 -> 134 | F41: 217.5 | G41: 183
... A54: 49 | B54: 200.6 | C54: 98 | D54: 200.1 | E54: =+E53+1 -> 147 | F54: 211.9 | G54: 196
B55: =SUM(B6:B54) -> 9987.3 | D55: =SUM(D6:D54) -> 9883.6 | F55: =SUM(F6:F54) -> 9756.4 | H55: =SUM(H6:H54) -> 1188 | J55: =SUM(J6:J54) -> 0
A56: Итого кип | B56: =COUNT(B6:B54,D6:D54,F6:F54,H6:H54,J6:J54) -> 153 | C56: Масса брутто | E56: =B55+D55+F55+H55+J55 -> 30815.3 | F56: Тары | G56: =B56*2.2 -> 336.6 | H56: Масса нетто | J56: =E56-G56 -> 30478.7
A57: Лаборант:
...

Sheet 234
A1: Акт покипного отвеса
A2: Лаборатория: хлопзавод при ООО "Navbahor Tekstil"
A3: Марка № | B3: 234 | I3: Корхона олди
I4: Жами
A5: № | B5: Масса | C5: № | D5: Масса | E5: № | F5: Масса | G5: № | H5: Масса | I5: № | J5: Масса
A6: 1 | B6: 202.1 | C6: 50 | D6: 216.4 | E6: 99 | F6: 205.8 | G6: 148 | H6: 209.7 | I6: 197 | J6: 185.2
A7: 2 | B7: 200.5 | C7: 51 | D7: 211.9 | E7: 100 | F7: 205.4 | G7: 149 | H7: 202.5 | I7: 198 | J7: 189
A8: 3 | B8: 204.7 | C8: 52 | D8: 206.7 | E8: =+E7+1 -> 101 | F8: 207.8 | G8: 150 | H8: 202.3 | I8: 199 | J8: 181.1
A9: 4 | B9: 197.8 | C9: 53 | D9: 208.8 | E9: =+E8+1 -> 102 | F9: 201.1 | G9: 151 | H9: 210.3 | I9: 200 | J9: 192.1
A10: 5 | B10: 205.41 | C10: 54 | D10: 204.8 | E10: =+E9+1 -> 103 | F10: 204.2 | G10: 152 | H10: 211.5 | I10: 201 | J10: 201.1
A11: 6 | B11: 206 | C11: 55 | D11: 201.9 | E11: =+E10+1 -> 104 | F11: 197.7 | G11: 153 | H11: 207.6 | I11: 202 | J11: 193.6
A12: 7 | B12: 197.7 | C12: 56 | D12: 211.2 | E12: =+E11+1 -> 105 | F12: 202.8 | G12: 154 | H12: 214.4 | I12: 203 | J12: 189.2
A13: 8 | B13: 202.4 | C13: 57 | D13: 207.2 | E13: =+E12+1 -> 106 | F13: 209.7 | G13: 155 | H13: 217.9 | I13: 204 | J13: 179.7
A14: 9 | B14: 199.2 | C14: 58 | D14: 204.4 | E14: =+E13+1 -> 107 | F14: 205.5 | G14: 156 | H14: 210 | I14: 205 | J14: 188.9
A15: 10 | B15: 205.3 | C15: 59 | D15: 204.1 | E15: =+E14+1 -> 108 | F15: 198.1 | G15: 157 | H15: 229.2 | I15: 206 | J15: 185
A16: 11 | B16: 211 | C16: 60 | D16: 202.5 | E16: =+E15+1 -> 109 | F16: 214.7 | G16: 158 | H16: 192.3 | I16: 207 | J16: 182.6
A17: 12 | B17: 201.7 | C17: 61 | D17: 209.8 | E17: =+E16+1 -> 110 | F17: 207.1 | G17: 159 | H17: 203.3 | I17: 208 | J17: 180.4
A18: 13 | B18: 198.3 | C18: 62 | D18: 211.4 | E18: =+E17+1 -> 111 | F18: 212.5 | G18: 160 | H18: 213.3 | I18: 209 | J18: 197.1
A19: 14 | B19: 200.7 | C19: 63 | D19: 206 | E19: =+E18+1 -> 112 | F19: 202.5 | G19: 161 | H19: 187.4 | I19: 210 | J19: 193.7
... A29: 24 | B29: 206.8 | C29: 73 | D29: 210.4 | E29: =+E28+1 -> 122 | F29: 213.3 | G29: 171 | H29: 193.6 | I29: 220 | J29: 198.7
A30: 25 | B30: 201.9 | C30: 74 | D30: 215.1 | E30: =+E29+1 -> 123 | F30: 211.7 | G30: 172 | H30: 208.3
A31: 26 | B31: 211.2 | C31: 75 | D31: 210.6 | E31: =+E30+1 -> 124 | F31: 205.3 | G31: 173 | H31: 179.9
A32: 27 | B32: 200.5 | C32: 76 | D32: 204.8 | E32: =+E31+1 -> 125 | F32: 200.4 | G32: 174 | H32: 208.2
A33: 28 | B33: 202.9 | C33: 77 | D33: 205 | E33: =+E32+1 -> 126 | F33: 206.8 | G33: 175 | H33: 205.6
A34: 29 | B34: 203 | C34: 78 | D34: 208.2 | E34: =+E33+1 -> 127 | F34: 211.5 | G34: 176 | H34: 192.9
A35: 30 | B35: 207.9 | C35: 79 | D35: 209.1 | E35: =+E34+1 -> 128 | F35: 210.9 | G35: 177 | H35: 174.9
A36: 31 | B36: 208.7 | C36: 80 | D36: 208.9 | E36: =+E35+1 -> 129 | F36: 217.4 | G36: 178 | H36: 193.9
A37: 32 | B37: 205.7 | C37: 81 | D37: 210.2 | E37: =+E36+1 -> 130 | F37: 205.7 | G37: 179 | H37: 209.7
A38: 33 | B38: 202.2 | C38: 82 | D38: 213.7 | E38: =+E37+1 -> 131 | F38: 206.6 | G38: 180 | H38: 181.8
A39: 34 | B39: 206.2 | C39: 83 | D39: 203.9 | E39: =+E38+1 -> 132 | F39: 204.9 | G39: 181 | H39: 196.4
A40: 35 | B40: 203.5 | C40: 84 | D40: 208.4 | E40: =+E39+1 -> 133 | F40: 197.8 | G40: 182 | H40: 191.5
A41: 36 | B41: 201.3 | C41: 85 | D41: 209.1 | E41: =+E40+1 -> 134 | F41: 205 | G41: 183 | H41: 196.3
... A54: 49 | B54: 208.6 | C54: 98 | D54: 207.2 | E54: =+E53+1 -> 147 | F54: 196.2 | G54: 196 | H54: 178.8
B55: =SUM(B6:B54) -> 10040.61 | D55: =SUM(D6:D54) -> 10207.7 | F55: =SUM(F6:F54) -> 10117.8 | H55: =SUM(H6:H54) -> 9494.9 | J55: =SUM(J6:J54) -> 4538.6
A56: Итого кип | B56: =COUNT(B6:B54,D6:D54,F6:F54,H6:H54,J6:J54) -> 220 | C56: Масса брутто | E56: =B55+D55+F55+H55+J55 -> 44399.61 | F56: Тары | G56: =B56*2.2 -> 484 | H56: Масса нетто | J56: =E56-G56 -> 43915.61
A57: Лаборант:
F59: Тара | G59: 2.2

Sheet 233
A1: Акт покипного отвеса | L1: Акт покипного отвеса | W1: Акт покипного отвеса
A2: Лаборатория: хлопзавод при ООО "Navbahor Tekstil" | L2: Лаборатория: хлопзавод при ООО "Navbahor Tekstil" | W2: Лаборатория: хлопзавод при ООО "Navbahor Tekstil"
A3: Марка № | B3: 233 | I3: Корхона олди | L3: Марка № | M3: 233 | T3: Корхона олди | W3: Марка № | X3: 233 | AE3: Корхона олди
I4: Жами | T4: 1 яхши | AE4: 1 урта
A5: № | B5: Масса | C5: № | D5: Масса | E5: № | F5: Масса | G5: № | H5: Масса | I5: № | J5: Масса | L5: № | M5: Масса | N5: № | O5: Масса | P5: № | Q5: Масса | R5: № | S5: Масса | T5: № | U5: Масса | W5: № | X5: Масса | Y5: № | Z5: Масса | AA5: № | AB5: Масса | AC5: № | AD5: Масса | AE5: № | AF5: Масса
A6: 1 | B6: 208.5 | C6: 50 | D6: 209 | E6: 99 | F6: 203.5 | G6: 148 | H6: 206.6 | I6: 197 | J6: 205.8 | L6: 1 | N6: 50 | O6: 209 | P6: 99 | Q6: 203.5 | R6: 148 | S6: 206.6 | T6: 197 | W6: 1 | X6: 208.5 | Y6: 50 | AA6: 99 | AC6: 148 | AE6: 197 | AF6: 205.8
A7: 2 | B7: 206.9 | C7: 51 | D7: 207.3 | E7: 100 | F7: 206.6 | G7: 149 | H7: 201.7 | I7: 198 | J7: 199.7 | L7: 2 | N7: 51 | O7: 207.3 | P7: 100 | Q7: 206.6 | R7: 149 | S7: 201.7 | T7: 198 | W7: 2 | X7: 206.9 | Y7: 51 | AA7: 100 | AC7: 149 | AE7: 198 | AF7: 199.7
A8: 3 | B8: 212.1 | C8: 52 | D8: 214.8 | E8: =+E7+1 -> 101 | F8: 207.2 | G8: 150 | H8: 206.3 | I8: 199 | J8: 201.5 | L8: 3 | N8: 52 | O8: 214.8 | P8: =+P7+1 -> 101 | Q8: 207.2 | R8: 150 | S8: 206.3 | T8: 199 | W8: 3 | X8: 212.1 | Y8: 52 | AA8: =+AA7+1 -> 101 | AC8: 150 | AE8: 199 | AF8: 201.5
A9: 4 | B9: 209.4 | C9: 53 | D9: 214.5 | E9: =+E8+1 -> 102 | F9: 211.3 | G9: 151 | H9: 204.3 | I9: 200 | J9: 204.9 | L9: 4 | N9: 53 | O9: 214.5 | P9: =+P8+1 -> 102 | Q9: 211.3 | R9: 151 | S9: 204.3 | T9: 200 | W9: 4 | X9: 209.4 | Y9: 53 | AA9: =+AA8+1 -> 102 | AC9: 151 | AE9: 200 | AF9: 204.9
A10: 5 | B10: 212.5 | C10: 54 | D10: 212.4 | E10: =+E9+1 -> 103 | F10: 209.1 | G10: 152 | H10: 200.4 | I10: 201 | J10: 200 | L10: 5 | N10: 54 | O10: 212.4 | P10: =+P9+1 -> 103 | Q10: 209.1 | R10: 152 | S10: 200.4 | T10: 201 | W10: 5 | X10: 212.5 | Y10: 54 | AA10: =+AA9+1 -> 103 | AC10: 152 | AE10: 201 | AF10: 200
A11: 6 | B11: 209.5 | C11: 55 | D11: 207.5 | E11: =+E10+1 -> 104 | F11: 203.5 | G11: 153 | H11: 200.3 | I11: 202 | J11: 198.5 | L11: 6 | N11: 55 | O11: 207.5 | P11: =+P10+1 -> 104 | Q11: 203.5 | R11: 153 | S11: 200.3 | T11: 202 | W11: 6 | X11: 209.5 | Y11: 55 | AA11: =+AA10+1 -> 104 | AC11: 153 | AE11: 202 | AF11: 198.5
A12: 7 | B12: 205.6 | C12: 56 | D12: 202.1 | E12: =+E11+1 -> 105 | F12: 212.4 | G12: 154 | H12: 204.7 | I12: 203 | J12: 203.9 | L12: 7 | N12: 56 | O12: 202.1 | P12: =+P11+1 -> 105 | Q12: 212.4 | R12: 154 | S12: 204.7 | T12: 203 | W12: 7 | X12: 205.6 | Y12: 56 | AA12: =+AA11+1 -> 105 | AC12: 154 | AE12: 203 | AF12: 203.9
A13: 8 | B13: 207.6 | C13: 57 | D13: 202.1 | E13: =+E12+1 -> 106 | F13: 208.5 | G13: 155 | H13: 204.2 | I13: 204 | J13: 201.4 | L13: 8 | N13: 57 | O13: 202.1 | P13: =+P12+1 -> 106 | Q13: 208.5 | R13: 155 | S13: 204.2 | T13: 204 | W13: 8 | X13: 207.6 | Y13: 57 | AA13: =+AA12+1 -> 106 | AC13: 155 | AE13: 204 | AF13: 201.4
A14: 9 | B14: 204.1 | C14: 58 | D14: 202.7 | E14: =+E13+1 -> 107 | F14: 199.3 | G14: 156 | H14: 198.8 | I14: 205 | J14: 198.9 | L14: 9 | N14: 58 | O14: 202.7 | P14: =+P13+1 -> 107 | Q14: 199.3 | R14: 156 | S14: 198.8 | T14: 205 | W14: 9 | X14: 204.1 | Y14: 58 | AA14: =+AA13+1 -> 107 | AC14: 156 | AE14: 205 | AF14: 198.9
A15: 10 | B15: 206.5 | C15: 59 | D15: 195.8 | E15: =+E14+1 -> 108 | F15: 197.4 | G15: 157 | H15: 193.7 | I15: 206 | J15: 205.2 | L15: 10 | N15: 59 | O15: 195.8 | P15: =+P14+1 -> 108 | Q15: 197.4 | R15: 157 | S15: 193.7 | T15: 206 | W15: 10 | X15: 206.5 | Y15: 59 | AA15: =+AA14+1 -> 108 | AC15: 157 | AE15: 206 | AF15: 205.2
A16: 11 | B16: 211.6 | C16: 60 | D16: 214 | E16: =+E15+1 -> 109 | F16: 190.1 | G16: 158 | H16: 209.3 | I16: 207 | J16: 195.4 | L16: 11 | N16: 60 | O16: 214 | P16: =+P15+1 -> 109 | Q16: 190.1 | R16: 158 | S16: 209.3 | T16: 207 | W16: 11 | X16: 211.6 | Y16: 60 | AA16: =+AA15+1 -> 109 | AC16: 158 | AE16: 207 | AF16: 195.4
A17: 12 | B17: 204.4 | C17: 61 | D17: 208.7 | E17: =+E16+1 -> 110 | F17: 205.6 | G17: 159 | H17: 196.5 | I17: 208 | J17: 197.3 | L17: 12 | N17: 61 | O17: 208.7 | P17: =+P16+1 -> 110 | Q17: 205.6 | R17: 159 | S17: 196.5 | T17: 208 | W17: 12 | X17: 204.4 | Y17: 61 | AA17: =+AA16+1 -> 110 | AC17: 159 | AE17: 208 | AF17: 197.3
A18: 13 | B18: 205.1 | C18: 62 | D18: 211.8 | E18: =+E17+1 -> 111 | F18: 209.6 | G18: 160 | H18: 204.6 | I18: 209 | J18: 192.5 | L18: 13 | N18: 62 | O18: 211.8 | P18: =+P17+1 -> 111 | Q18: 209.6 | R18: 160 | S18: 204.6 | T18: 209 | W18: 13 | X18: 205.1 | Y18: 62 | AA18: =+AA17+1 -> 111 | AC18: 160 | AE18: 209 | AF18: 192.5
A19: 14 | B19: 210.8 | C19: 63 | D19: 209.4 | E19: =+E18+1 -> 112 | F19: 202.9 | G19: 161 | H19: 205.2 | I19: 210 | J19: 200.9 | L19: 14 | N19: 63 | O19: 209.4 | P19: =+P18+1 -> 112 | Q19: 202.9 | R19: 161 | S19: 205.2 | T19: 210 | W19: 14 | X19: 210.8 | Y19: 63 | AA19: =+AA18+1 -> 112 | AC19: 161 | AE19: 210 | AF19: 200.9
... A28: 23 | B28: 205.7 | C28: 72 | D28: 210 | E28: =+E27+1 -> 121 | F28: 200.9 | G28: 170 | H28: 207.9 | I28: 219 | J28: 203.1 | L28: 23 | N28: 72 | O28: 210 | P28: =+P27+1 -> 121 | Q28: 200.9 | R28: 170 | S28: 207.9 | T28: 219 | W28: 23 | X28: 205.7 | Y28: 72 | AA28: =+AA27+1 -> 121 | AC28: 170 | AE28: 219 | AF28: 203.1
A29: 24 | B29: 201.7 | C29: 73 | D29: 203 | E29: =+E28+1 -> 122 | F29: 204.9 | G29: 171 | H29: 197.2 | I29: 220 | J29: 200.6 | L29: 24 | N29: 73 | O29: 203 | P29: =+P28+1 -> 122 | Q29: 204.9 | R29: 171 | T29: 220 | W29: 24 | X29: 201.7 | Y29: 73 | AA29: =+AA28+1 -> 122 | AC29: 171 | AD29: 197.2 | AE29: 220 | AF29: 200.6
A30: 25 | B30: 213.8 | C30: 74 | D30: 198.8 | E30: =+E29+1 -> 123 | F30: 202.9 | G30: 172 | H30: 201.1 | L30: 25 | N30: 74 | O30: 198.8 | P30: =+P29+1 -> 123 | Q30: 202.9 | R30: 172 | W30: 25 | X30: 213.8 | Y30: 74 | AA30: =+AA29+1 -> 123 | AC30: 172 | AD30: 201.1
A31: 26 | B31: 205 | C31: 75 | D31: 204.7 | E31: =+E30+1 -> 124 | F31: 205.5 | G31: 173 | H31: 208.9 | L31: 26 | N31: 75 | O31: 204.7 | P31: =+P30+1 -> 124 | Q31: 205.5 | R31: 173 | W31: 26 | X31: 205 | Y31: 75 | AA31: =+AA30+1 -> 124 | AC31: 173 | AD31: 208.9
A32: 27 | B32: 206.7 | C32: 76 | D32: 212.5 | E32: =+E31+1 -> 125 | F32: 206.1 | G32: 174 | H32: 203.8 | L32: 27 | N32: 76 | O32: 212.5 | P32: =+P31+1 -> 125 | Q32: 206.1 | R32: 174 | W32: 27 | X32: 206.7 | Y32: 76 | AA32: =+AA31+1 -> 125 | AC32: 174 | AD32: 203.8
A33: 28 | B33: 212.8 | C33: 77 | D33: 204.2 | E33: =+E32+1 -> 126 | F33: 213.2 | G33: 175 | H33: 206.9 | L33: 28 | N33: 77 | O33: 204.2 | P33: =+P32+1 -> 126 | Q33: 213.2 | R33: 175 | W33: 28 | X33: 212.8 | Y33: 77 | AA33: =+AA32+1 -> 126 | AC33: 175 | AD33: 206.9
A34: 29 | B34: 209 | C34: 78 | D34: 206.5 | E34: =+E33+1 -> 127 | F34: 209.4 | G34: 176 | H34: 203.6 | L34: 29 | N34: 78 | O34: 206.5 | P34: =+P33+1 -> 127 | Q34: 209.4 | R34: 176 | W34: 29 | X34: 209 | Y34: 78 | AA34: =+AA33+1 -> 127 | AC34: 176 | AD34: 203.6
A35: 30 | B35: 208.2 | C35: 79 | D35: 208.5 | E35: =+E34+1 -> 128 | F35: 205.9 | G35: 177 | H35: 207.5 | L35: 30 | N35: 79 | O35: 208.5 | P35: =+P34+1 -> 128 | Q35: 205.9 | R35: 177 | W35: 30 | X35: 208.2 | Y35: 79 | AA35: =+AA34+1 -> 128 | AC35: 177 | AD35: 207.5
A36: 31 | B36: 203.8 | C36: 80 | D36: 211.5 | E36: =+E35+1 -> 129 | F36: 203.4 | G36: 178 | H36: 202.4 | L36: 31 | N36: 80 | O36: 211.5 | P36: =+P35+1 -> 129 | Q36: 203.4 | R36: 178 | W36: 31 | X36: 203.8 | Y36: 80 | AA36: =+AA35+1 -> 129 | AC36: 178 | AD36: 202.4
A37: 32 | B37: 201.9 | C37: 81 | D37: 204.9 | E37: =+E36+1 -> 130 | F37: 206.7 | G37: 179 | H37: 203.6 | L37: 32 | N37: 81 | O37: 204.9 | P37: =+P36+1 -> 130 | Q37: 206.7 | R37: 179 | W37: 32 | X37: 201.9 | Y37: 81 | AA37: =+AA36+1 -> 130 | AC37: 179 | AD37: 203.6
A38: 33 | B38: 206.4 | C38: 82 | D38: 214.2 | E38: =+E37+1 -> 131 | F38: 208.8 | G38: 180 | H38: 201.2 | L38: 33 | N38: 82 | O38: 214.2 | P38: =+P37+1 -> 131 | Q38: 208.8 | R38: 180 | W38: 33 | X38: 206.4 | Y38: 82 | AA38: =+AA37+1 -> 131 | AC38: 180 | AD38: 201.2
A39: 34 | B39: 212 | C39: 83 | D39: 210.3 | E39: =+E38+1 -> 132 | F39: 207.8 | G39: 181 | H39: 205.2 | L39: 34 | N39: 83 | O39: 210.3 | P39: =+P38+1 -> 132 | Q39: 207.8 | R39: 181 | W39: 34 | X39: 212 | Y39: 83 | AA39: =+AA38+1 -> 132 | AC39: 181 | AD39: 205.2
A40: 35 | B40: 204 | C40: 84 | D40: 208.6 | E40: =+E39+1 -> 133 | F40: 208.3 | G40: 182 | H40: 199.6 | L40: 35 | N40: 84 | O40: 208.6 | P40: =+P39+1 -> 133 | Q40: 208.3 | R40: 182 | W40: 35 | X40: 204 | Y40: 84 | AA40: =+AA39+1 -> 133 | AC40: 182 | AD40: 199.6
A41: 36 | B41: 210 | C41: 85 | D41: 204.6 | E41: =+E40+1 -> 134 | F41: 209 | G41: 183 | H41: 196.2 | L41: 36 | N41: 85 | O41: 204.6 | P41: =+P40+1 -> 134 | Q41: 209 | R41: 183 | W41: 36 | X41: 210 | Y41: 85 | AA41: =+AA40+1 -> 134 | AC41: 183 | AD41: 196.2
... A45: 40 | B45: 206.1 | C45: 89 | D45: 204.9 | E45: =+E44+1 -> 138 | F45: 214.7 | G45: 187 | H45: 172.6 | L45: 40 | N45: 89 | O45: 204.9 | P45: =+P44+1 -> 138 | Q45: 214.7 | R45: 187 | W45: 40 | X45: 206.1 | Y45: 89 | AA45: =+AA44+1 -> 138 | AC45: 187 | AD45: 172.6
A46: 41 | B46: 209.7 | C46: 90 | D46: 206.8 | E46: =+E45+1 -> 139 | F46: 203.9 | G46: 188 | H46: 205.6 | L46: 41 | M46: 209.7 | N46: 90 | O46: 206.8 | P46: =+P45+1 -> 139 | Q46: 203.9 | R46: 188 | W46: 41 | Y46: 90 | AA46: =+AA45+1 -> 139 | AC46: 188 | AD46: 205.6
A47: 42 | B47: 206.5 | C47: 91 | D47: 208.9 | E47: =+E46+1 -> 140 | F47: 203.7 | G47: 189 | H47: 206.6 | L47: 42 | M47: 206.5 | N47: 91 | O47: 208.9 | P47: =+P46+1 -> 140 | Q47: 203.7 | R47: 189 | W47: 42 | Y47: 91 | AA47: =+AA46+1 -> 140 | AC47: 189 | AD47: 206.6
A48: 43 | B48: 212.8 | C48: 92 | D48: 211.9 | E48: =+E47+1 -> 141 | F48: 203.9 | G48: 190 | H48: 199.6 | L48: 43 | M48: 212.8 | N48: 92 | O48: 211.9 | P48: =+P47+1 -> 141 | Q48: 203.9 | R48: 190 | W48: 43 | Y48: 92 | AA48: =+AA47+1 -> 141 | AC48: 190 | AD48: 199.6
A49: 44 | B49: 211.8 | C49: 93 | D49: 206.4 | E49: =+E48+1 -> 142 | F49: 204.4 | G49: 191 | H49: 202.6 | L49: 44 | M49: 211.8 | N49: 93 | O49: 206.4 | P49: =+P48+1 -> 142 | Q49: 204.4 | R49: 191 | W49: 44 | Y49: 93 | AA49: =+AA48+1 -> 142 | AC49: 191 | AD49: 202.6
A50: 45 | B50: 208.7 | C50: 94 | D50: 198.2 | E50: =+E49+1 -> 143 | F50: 208.1 | G50: 192 | H50: 201.3 | L50: 45 | M50: 208.7 | N50: 94 | O50: 198.2 | P50: =+P49+1 -> 143 | Q50: 208.1 | R50: 192 | W50: 45 | Y50: 94 | AA50: =+AA49+1 -> 143 | AC50: 192 | AD50: 201.3
A51: 46 | B51: 203.6 | C51: 95 | D51: 194 | E51: =+E50+1 -> 144 | F51: 208.8 | G51: 193 | H51: 201.2 | L51: 46 | M51: 203.6 | N51: 95 | O51: 194 | P51: =+P50+1 -> 144 | Q51: 208.8 | R51: 193 | W51: 46 | Y51: 95 | AA51: =+AA50+1 -> 144 | AC51: 193 | AD51: 201.2
...

Sheet 232
A1: Акт покипного отвеса | L1: Акт покипного отвеса | W1: Акт покипного отвеса
A2: Лаборатория: хлопзавод при ООО "Navbahor Tekstil" | L2: Лаборатория: хлопзавод при ООО "Navbahor Tekstil" | W2: Лаборатория: хлопзавод при ООО "Navbahor Tekstil"
A3: Марка № | B3: 232 | I3: Корхона олди | L3: Марка № | M3: 232 | T3: Корхона олди | W3: Марка № | X3: 232 | AE3: Корхона олди
I4: Жами | T4: 1 яхши | AE4: 1 урта
A5: № | B5: Масса | C5: № | D5: Масса | E5: № | F5: Масса | G5: № | H5: Масса | I5: № | J5: Масса | L5: № | M5: Масса | N5: № | O5: Масса | P5: № | Q5: Масса | R5: № | S5: Масса | T5: № | U5: Масса | W5: № | X5: Масса | Y5: № | Z5: Масса | AA5: № | AB5: Масса | AC5: № | AD5: Масса | AE5: № | AF5: Масса
A6: 1 | B6: 201.4 | C6: 50 | D6: 203.1 | E6: 99 | F6: 205.8 | G6: 148 | H6: 202.6 | I6: 197 | J6: 211.2 | L6: 1 | N6: 50 | O6: 203.1 | P6: 99 | R6: 148 | S6: 202.6 | T6: 197 | W6: 1 | X6: 201.4 | Y6: 50 | AA6: 99 | AB6: 205.8 | AC6: 148 | AE6: 197 | AF6: 211.2
A7: 2 | B7: 188 | C7: 51 | D7: 202.2 | E7: 100 | F7: 206.8 | G7: 149 | H7: 206.1 | I7: 198 | J7: 212 | L7: 2 | N7: 51 | O7: 202.2 | P7: 100 | R7: 149 | S7: 206.1 | T7: 198 | W7: 2 | X7: 188 | Y7: 51 | AA7: 100 | AB7: 206.8 | AC7: 149 | AE7: 198 | AF7: 212
A8: 3 | B8: 209.4 | C8: 52 | D8: 200.6 | E8: =+E7+1 -> 101 | F8: 207.3 | G8: 150 | H8: 202 | I8: 199 | J8: 213.6 | L8: 3 | N8: 52 | O8: 200.6 | P8: =+P7+1 -> 101 | R8: 150 | S8: 202 | T8: 199 | W8: 3 | X8: 209.4 | Y8: 52 | AA8: =+AA7+1 -> 101 | AB8: 207.3 | AC8: 150 | AE8: 199 | AF8: 213.6
A9: 4 | B9: 182.4 | C9: 53 | D9: 204.4 | E9: =+E8+1 -> 102 | F9: 204.5 | G9: 151 | H9: 204.2 | I9: 200 | J9: 205.3 | L9: 4 | N9: 53 | O9: 204.4 | P9: =+P8+1 -> 102 | R9: 151 | S9: 204.2 | T9: 200 | W9: 4 | X9: 182.4 | Y9: 53 | AA9: =+AA8+1 -> 102 | AB9: 204.5 | AC9: 151 | AE9: 200 | AF9: 205.3
A10: 5 | B10: 205.9 | C10: 54 | D10: 204.5 | E10: =+E9+1 -> 103 | F10: 199.5 | G10: 152 | H10: 208.2 | I10: 201 | J10: 201.7 | L10: 5 | N10: 54 | O10: 204.5 | P10: =+P9+1 -> 103 | R10: 152 | S10: 208.2 | T10: 201 | W10: 5 | X10: 205.9 | Y10: 54 | AA10: =+AA9+1 -> 103 | AB10: 199.5 | AC10: 152 | AE10: 201 | AF10: 201.7
A11: 6 | B11: 199 | C11: 55 | D11: 202.2 | E11: =+E10+1 -> 104 | F11: 198.9 | G11: 153 | H11: 208.5 | I11: 202 | J11: 209.6 | L11: 6 | N11: 55 | O11: 202.2 | P11: =+P10+1 -> 104 | R11: 153 | S11: 208.5 | T11: 202 | W11: 6 | X11: 199 | Y11: 55 | AA11: =+AA10+1 -> 104 | AB11: 198.9 | AC11: 153 | AE11: 202 | AF11: 209.6
A12: 7 | B12: 191.2 | C12: 56 | D12: 203.4 | E12: =+E11+1 -> 105 | F12: 204.2 | G12: 154 | H12: 202.7 | I12: 203 | J12: 212.2 | L12: 7 | N12: 56 | O12: 203.4 | P12: =+P11+1 -> 105 | R12: 154 | S12: 202.7 | T12: 203 | W12: 7 | X12: 191.2 | Y12: 56 | AA12: =+AA11+1 -> 105 | AB12: 204.2 | AC12: 154 | AE12: 203 | AF12: 212.2
A13: 8 | B13: 205.9 | C13: 57 | D13: 198.5 | E13: =+E12+1 -> 106 | F13: 197.3 | G13: 155 | H13: 199.6 | I13: 204 | J13: 207.1 | L13: 8 | N13: 57 | O13: 198.5 | P13: =+P12+1 -> 106 | R13: 155 | S13: 199.6 | T13: 204 | W13: 8 | X13: 205.9 | Y13: 57 | AA13: =+AA12+1 -> 106 | AB13: 197.3 | AC13: 155 | AE13: 204 | AF13: 207.1
A14: 9 | B14: 163.2 | C14: 58 | D14: 197 | E14: =+E13+1 -> 107 | F14: 202 | G14: 156 | H14: 204.8 | I14: 205 | J14: 208.7 | L14: 9 | N14: 58 | O14: 197 | P14: =+P13+1 -> 107 | R14: 156 | S14: 204.8 | T14: 205 | W14: 9 | X14: 163.2 | Y14: 58 | AA14: =+AA13+1 -> 107 | AB14: 202 | AC14: 156 | AE14: 205 | AF14: 208.7
A15: 10 | B15: 204.9 | C15: 59 | D15: 204.1 | E15: =+E14+1 -> 108 | F15: 201.7 | G15: 157 | H15: 203.9 | I15: 206 | J15: 208.5 | L15: 10 | N15: 59 | O15: 204.1 | P15: =+P14+1 -> 108 | R15: 157 | S15: 203.9 | T15: 206 | W15: 10 | X15: 204.9 | Y15: 59 | AA15: =+AA14+1 -> 108 | AB15: 201.7 | AC15: 157 | AE15: 206 | AF15: 208.5
A16: 11 | B16: 203.1 | C16: 60 | D16: 205.3 | E16: =+E15+1 -> 109 | F16: 206.1 | G16: 158 | H16: 204.4 | I16: 207 | J16: 207.7 | L16: 11 | N16: 60 | O16: 205.3 | P16: =+P15+1 -> 109 | R16: 158 | S16: 204.4 | T16: 207 | W16: 11 | X16: 203.1 | Y16: 60 | AA16: =+AA15+1 -> 109 | AB16: 206.1 | AC16: 158 | AE16: 207 | AF16: 207.7
A17: 12 | B17: 193.6 | C17: 61 | D17: 207.4 | E17: =+E16+1 -> 110 | F17: 206 | G17: 159 | H17: 200.1 | I17: 208 | J17: 211.5 | L17: 12 | N17: 61 | O17: 207.4 | P17: =+P16+1 -> 110 | R17: 159 | S17: 200.1 | T17: 208 | W17: 12 | X17: 193.6 | Y17: 61 | AA17: =+AA16+1 -> 110 | AB17: 206 | AC17: 159 | AE17: 208 | AF17: 211.5
A18: 13 | B18: 208.5 | C18: 62 | D18: 198.6 | E18: =+E17+1 -> 111 | F18: 207 | G18: 160 | H18: 206.4 | I18: 209 | J18: 213.3 | L18: 13 | N18: 62 | O18: 198.6 | P18: =+P17+1 -> 111 | R18: 160 | S18: 206.4 | T18: 209 | W18: 13 | X18: 208.5 | Y18: 62 | AA18: =+AA17+1 -> 111 | AB18: 207 | AC18: 160 | AE18: 209 | AF18: 213.3
A19: 14 | B19: 182.6 | C19: 63 | D19: 207.8 | E19: =+E18+1 -> 112 | F19: 202.3 | G19: 161 | H19: 198.8 | I19: 210 | J19: 210.2 | L19: 14 | N19: 63 | O19: 207.8 | P19: =+P18+1 -> 112 | R19: 161 | S19: 198.8 | T19: 210 | W19: 14 | X19: 182.6 | Y19: 63 | AA19: =+AA18+1 -> 112 | AB19: 202.3 | AC19: 161 | AE19: 210 | AF19: 210.2
... A29: 24 | B29: 207.3 | C29: 73 | D29: 210.7 | E29: =+E28+1 -> 122 | F29: 191.2 | G29: 171 | H29: 201.5 | I29: 220 | J29: 205.7 | L29: 24 | N29: 73 | O29: 210.7 | P29: =+P28+1 -> 122 | R29: 171 | S29: 201.5 | T29: 220 | W29: 24 | X29: 207.3 | Y29: 73 | AA29: =+AA28+1 -> 122 | AB29: 191.2 | AC29: 171 | AE29: 220 | AF29: 205.7
A30: 25 | B30: 173.1 | C30: 74 | D30: 201.4 | E30: =+E29+1 -> 123 | F30: 205.9 | G30: 172 | H30: 209.4 | L30: 25 | N30: 74 | O30: 201.4 | P30: =+P29+1 -> 123 | R30: 172 | S30: 209.4 | W30: 25 | X30: 173.1 | Y30: 74 | AA30: =+AA29+1 -> 123 | AB30: 205.9 | AC30: 172
A31: 26 | B31: 207.5 | C31: 75 | D31: 199.2 | E31: =+E30+1 -> 124 | F31: 201.7 | G31: 173 | H31: 203.4 | L31: 26 | N31: 75 | O31: 199.2 | P31: =+P30+1 -> 124 | R31: 173 | S31: 203.4 | W31: 26 | X31: 207.5 | Y31: 75 | AA31: =+AA30+1 -> 124 | AB31: 201.7 | AC31: 173
A32: 27 | B32: 203.9 | C32: 76 | D32: 204.4 | E32: =+E31+1 -> 125 | F32: 199.9 | G32: 174 | H32: 197.8 | L32: 27 | N32: 76 | O32: 204.4 | P32: =+P31+1 -> 125 | R32: 174 | S32: 197.8 | W32: 27 | X32: 203.9 | Y32: 76 | AA32: =+AA31+1 -> 125 | AB32: 199.9 | AC32: 174
A33: 28 | B33: 181.9 | C33: 77 | D33: 198.5 | E33: =+E32+1 -> 126 | F33: 203.3 | G33: 175 | H33: 202.7 | L33: 28 | N33: 77 | O33: 198.5 | P33: =+P32+1 -> 126 | R33: 175 | S33: 202.7 | W33: 28 | X33: 181.9 | Y33: 77 | AA33: =+AA32+1 -> 126 | AB33: 203.3 | AC33: 175
A34: 29 | B34: 197.2 | C34: 78 | D34: 202.3 | E34: =+E33+1 -> 127 | F34: 207.5 | G34: 176 | H34: 206.7 | L34: 29 | N34: 78 | O34: 202.3 | P34: =+P33+1 -> 127 | R34: 176 | S34: 206.7 | W34: 29 | X34: 197.2 | Y34: 78 | AA34: =+AA33+1 -> 127 | AB34: 207.5 | AC34: 176
A35: 30 | B35: 197.2 | C35: 79 | D35: 205.1 | E35: =+E34+1 -> 128 | F35: 202.2 | G35: 177 | H35: 209.5 | L35: 30 | N35: 79 | O35: 205.1 | P35: =+P34+1 -> 128 | R35: 177 | S35: 209.5 | W35: 30 | X35: 197.2 | Y35: 79 | AA35: =+AA34+1 -> 128 | AB35: 202.2 | AC35: 177
A36: 31 | B36: 201.7 | C36: 80 | D36: 207.5 | E36: =+E35+1 -> 129 | F36: 206.5 | G36: 178 | H36: 203.8 | L36: 31 | M36: 201.7 | N36: 80 | O36: 207.5 | P36: =+P35+1 -> 129 | R36: 178 | S36: 203.8 | W36: 31 | Y36: 80 | AA36: =+AA35+1 -> 129 | AB36: 206.5 | AC36: 178
A37: 32 | B37: 195.5 | C37: 81 | D37: 206.4 | E37: =+E36+1 -> 130 | F37: 209.5 | G37: 179 | H37: 210.8 | L37: 32 | M37: 195.5 | N37: 81 | O37: 206.4 | P37: =+P36+1 -> 130 | R37: 179 | S37: 210.8 | W37: 32 | Y37: 81 | AA37: =+AA36+1 -> 130 | AB37: 209.5 | AC37: 179
A38: 33 | B38: 200.9 | C38: 82 | D38: 199.9 | E38: =+E37+1 -> 131 | F38: 210.3 | G38: 180 | H38: 209.4 | L38: 33 | M38: 200.9 | N38: 82 | O38: 199.9 | P38: =+P37+1 -> 131 | R38: 180 | S38: 209.4 | W38: 33 | Y38: 82 | AA38: =+AA37+1 -> 131 | AB38: 210.3 | AC38: 180
A39: 34 | B39: 203.9 | C39: 83 | D39: 206.1 | E39: =+E38+1 -> 132 | F39: 202.5 | G39: 181 | H39: 214.2 | L39: 34 | M39: 203.9 | N39: 83 | O39: 206.1 | P39: =+P38+1 -> 132 | R39: 181 | S39: 214.2 | W39: 34 | Y39: 83 | AA39: =+AA38+1 -> 132 | AB39: 202.5 | AC39: 181
A40: 35 | B40: 193.1 | C40: 84 | D40: 200.8 | E40: =+E39+1 -> 133 | F40: 207.1 | G40: 182 | H40: 210.8 | L40: 35 | M40: 193.1 | N40: 84 | O40: 200.8 | P40: =+P39+1 -> 133 | R40: 182 | S40: 210.8 | W40: 35 | Y40: 84 | AA40: =+AA39+1 -> 133 | AB40: 207.1 | AC40: 182
A41: 36 | B41: 196.5 | C41: 85 | D41: 211.9 | E41: =+E40+1 -> 134 | F41: 202.7 | G41: 183 | H41: 208.5 | L41: 36 | M41: 196.5 | N41: 85 | O41: 211.9 | P41: =+P40+1 -> 134 | R41: 183 | S41: 208.5 | W41: 36 | Y41: 85 | AA41: =+AA40+1 -> 134 | AB41: 202.7 | AC41: 183
A42: 37 | B42: 197 | C42: 86 | D42: 206.9 | E42: =+E41+1 -> 135 | F42: 201.5 | G42: 184 | H42: 205.4 | L42: 37 | M42: 197 | N42: 86 | O42: 206.9 | P42: =+P41+1 -> 135 | R42: 184 | S42: 205.4 | W42: 37 | Y42: 86 | AA42: =+AA41+1 -> 135 | AB42: 201.5 | AC42: 184
A43: 38 | B43: 193.4 | C43: 87 | D43: 202.8 | E43: =+E42+1 -> 136 | F43: 207 | G43: 185 | H43: 206.2 | L43: 38 | M43: 193.4 | N43: 87 | O43: 202.8 | P43: =+P42+1 -> 136 | R43: 185 | S43: 206.2 | W43: 38 | Y43: 87 | AA43: =+AA42+1 -> 136 | AB43: 207 | AC43: 185
A44: 39 | B44: 194.5 | C44: 88 | D44: 207.9 | E44: =+E43+1 -> 137 | F44: 200 | G44: 186 | H44: 208.2 | L44: 39 | M44: 194.5 | N44: 88 | O44: 207.9 | P44: =+P43+1 -> 137 | R44: 186 | S44: 208.2 | W44: 39 | Y44: 88 | AA44: =+AA43+1 -> 137 | AB44: 200 | AC44: 186
A45: 40 | B45: 198.9 | C45: 89 | D45: 200.9 | E45: =+E44+1 -> 138 | F45: 203.5 | G45: 187 | H45: 211.8 | L45: 40 | M45: 198.9 | N45: 89 | O45: 200.9 | P45: =+P44+1 -> 138 | Q45: 203.5 | R45: 187 | S45: 211.8 | W45: 40 | Y45: 89 | AA45: =+AA44+1 -> 138 | AC45: 187
A46: 41 | B46: 191.7 | C46: 90 | D46: 198.3 | E46: =+E45+1 -> 139 | F46: 202.9 | G46: 188 | H46: 206.7 | L46: 41 | M46: 191.7 | N46: 90 | O46: 198.3 | P46: =+P45+1 -> 139 | Q46: 202.9 | R46: 188 | S46: 206.7 | W46: 41 | Y46: 90 | AA46: =+AA45+1 -> 139 | AC46: 188
A47: 42 | B47: 192.1 | C47: 91 | D47: 202.5 | E47: =+E46+1 -> 140 | F47: 197.2 | G47: 189 | H47: 210.1 | L47: 42 | M47: 192.1 | N47: 91 | O47: 202.5 | P47: =+P46+1 -> 140 | Q47: 197.2 | R47: 189 | S47: 210.1 | W47: 42 | Y47: 91 | AA47: =+AA46+1 -> 140 | AC47: 189
A48: 43 | B48: 198.3 | C48: 92 | D48: 205.5 | E48: =+E47+1 -> 141 | F48: 160.2 | G48: 190 | H48: 208.6 | L48: 43 | M48: 198.3 | N48: 92 | O48: 205.5 | P48: =+P47+1 -> 141 | Q48: 160.2 | R48: 190 | S48: 208.6 | W48: 43 | Y48: 92 | AA48: =+AA47+1 -> 141 | AC48: 190
A49: 44 | B49: 207.2 | C49: 93 | D49: 202.8 | E49: =+E48+1 -> 142 | F49: 200.2 | G49: 191 | H49: 218.1 | L49: 44 | M49: 207.2 | N49: 93 | O49: 202.8 | P49: =+P48+1 -> 142 | Q49: 200.2 | R49: 191 | W49: 44 | Y49: 93 | AA49: =+AA48+1 -> 142 | AC49: 191 | AD49: 218.1
...

Sheet 231
A1: Акт покипного отвеса | L1: Акт покипного отвеса
A2: Лаборатория: хлопзавод при ООО "Navbahor Tekstil" | L2: Лаборатория: хлопзавод при ООО "Navbahor Tekstil"
A3: Марка № | B3: 231 | I3: Корхона олди | L3: Марка № | M3: 231 | T3: Корхона олди
I4: Жами | T4: 1 урта
A5: № | B5: Масса | C5: № | D5: Масса | E5: № | F5: Масса | G5: № | H5: Масса | I5: № | J5: Масса | L5: № | M5: Масса | N5: № | O5: Масса | P5: № | Q5: Масса | R5: № | S5: Масса | T5: № | U5: Масса
A6: 1 | B6: 197.1 | C6: 50 | D6: 204.7 | E6: 99 | F6: 210 | G6: 148 | H6: 187.5 | I6: 197 | J6: 206.5 | L6: 1 | M6: 197.1 | N6: 50 | O6: 204.7 | P6: 99 | Q6: 210 | R6: 148 | S6: 187.5 | T6: 197 | U6: 206.5
A7: 2 | B7: 213.9 | C7: 51 | D7: 210.6 | E7: 100 | F7: 185 | G7: 149 | H7: 206.1 | I7: 198 | J7: 170 | L7: 2 | M7: 213.9 | N7: 51 | O7: 210.6 | P7: 100 | Q7: 185 | R7: 149 | S7: 206.1 | T7: 198 | U7: 170
A8: 3 | B8: 210.1 | C8: 52 | D8: 207.6 | E8: =+E7+1 -> 101 | F8: 210.3 | G8: 150 | H8: 172.8 | I8: 199 | J8: 211.4 | L8: 3 | M8: 210.1 | N8: 52 | O8: 207.6 | P8: =+P7+1 -> 101 | Q8: 210.3 | R8: 150 | S8: 172.8 | T8: 199 | U8: 211.4
A9: 4 | B9: 181.7 | C9: 53 | D9: 210.5 | E9: =+E8+1 -> 102 | F9: 213.3 | G9: 151 | H9: 202.6 | I9: 200 | J9: 201.9 | L9: 4 | M9: 181.7 | N9: 53 | O9: 210.5 | P9: =+P8+1 -> 102 | Q9: 213.3 | R9: 151 | S9: 202.6 | T9: 200 | U9: 201.9
A10: 5 | B10: 206.8 | C10: 54 | D10: 208.7 | E10: =+E9+1 -> 103 | F10: 168.3 | G10: 152 | H10: 211.7 | I10: 201 | J10: 179.7 | L10: 5 | M10: 206.8 | N10: 54 | O10: 208.7 | P10: =+P9+1 -> 103 | Q10: 168.3 | R10: 152 | S10: 211.7 | T10: 201 | U10: 179.7
A11: 6 | B11: 202.8 | C11: 55 | D11: 194.9 | E11: =+E10+1 -> 104 | F11: 217.4 | G11: 153 | H11: 180.4 | I11: 202 | J11: 203.6 | L11: 6 | M11: 202.8 | N11: 55 | O11: 194.9 | P11: =+P10+1 -> 104 | Q11: 217.4 | R11: 153 | S11: 180.4 | T11: 202 | U11: 203.6
A12: 7 | B12: 190 | C12: 56 | D12: 210.9 | E12: =+E11+1 -> 105 | F12: 189.7 | G12: 154 | H12: 206.6 | I12: 203 | J12: 203.1 | L12: 7 | M12: 190 | N12: 56 | O12: 210.9 | P12: =+P11+1 -> 105 | Q12: 189.7 | R12: 154 | S12: 206.6 | T12: 203 | U12: 203.1
A13: 8 | B13: 208 | C13: 57 | D13: 196.3 | E13: =+E12+1 -> 106 | F13: 212.5 | G13: 155 | H13: 173 | I13: 204 | J13: 201.2 | L13: 8 | M13: 208 | N13: 57 | O13: 196.3 | P13: =+P12+1 -> 106 | Q13: 212.5 | R13: 155 | S13: 173 | T13: 204 | U13: 201.2
A14: 9 | B14: 212.4 | C14: 58 | D14: 211.5 | E14: =+E13+1 -> 107 | F14: 210.1 | G14: 156 | H14: 205.6 | I14: 205 | J14: 170 | L14: 9 | M14: 212.4 | N14: 58 | O14: 211.5 | P14: =+P13+1 -> 107 | Q14: 210.1 | R14: 156 | S14: 205.6 | T14: 205 | U14: 170
A15: 10 | B15: 211.8 | C15: 59 | D15: 166.1 | E15: =+E14+1 -> 108 | F15: 171.1 | G15: 157 | H15: 208.9 | I15: 206 | J15: 204.2 | L15: 10 | M15: 211.8 | N15: 59 | O15: 166.1 | P15: =+P14+1 -> 108 | Q15: 171.1 | R15: 157 | S15: 208.9 | T15: 206 | U15: 204.2
A16: 11 | B16: 179.1 | C16: 60 | D16: 208 | E16: =+E15+1 -> 109 | F16: 208.1 | G16: 158 | H16: 211.4 | I16: 207 | J16: 169 | L16: 11 | M16: 179.1 | N16: 60 | O16: 208 | P16: =+P15+1 -> 109 | Q16: 208.1 | R16: 158 | S16: 211.4 | T16: 207 | U16: 169
A17: 12 | B17: 209.7 | C17: 61 | D17: 186 | E17: =+E16+1 -> 110 | F17: 199 | G17: 159 | H17: 212.2 | I17: 208 | J17: 199.3 | L17: 12 | M17: 209.7 | N17: 61 | O17: 186 | P17: =+P16+1 -> 110 | Q17: 199 | R17: 159 | S17: 212.2 | T17: 208 | U17: 199.3
A18: 13 | B18: 213.9 | C18: 62 | D18: 207.9 | E18: =+E17+1 -> 111 | F18: 207.1 | G18: 160 | H18: 186.5 | I18: 209 | J18: 199.8 | L18: 13 | M18: 213.9 | N18: 62 | O18: 207.9 | P18: =+P17+1 -> 111 | Q18: 207.1 | R18: 160 | S18: 186.5 | T18: 209 | U18: 199.8
A19: 14 | B19: 185.1 | C19: 63 | D19: 182.8 | E19: =+E18+1 -> 112 | F19: 176.4 | G19: 161 | H19: 213.6 | I19: 210 | J19: 178.7 | L19: 14 | M19: 185.1 | N19: 63 | O19: 182.8 | P19: =+P18+1 -> 112 | Q19: 176.4 | R19: 161 | S19: 213.6 | T19: 210 | U19: 178.7
... A29: 24 | B29: 205.53 | C29: 73 | D29: 212.8 | E29: =+E28+1 -> 122 | F29: 184.6 | G29: 171 | H29: 197 | I29: 220 | J29: 204.7 | L29: 24 | M29: 205.53 | N29: 73 | O29: 212.8 | P29: =+P28+1 -> 122 | Q29: 184.6 | R29: 171 | S29: 197 | T29: 220 | U29: 204.7
A30: 25 | B30: 211.7 | C30: 74 | D30: 212 | E30: =+E29+1 -> 123 | F30: 207.3 | G30: 172 | H30: 206.4 | L30: 25 | M30: 211.7 | N30: 74 | O30: 212 | P30: =+P29+1 -> 123 | Q30: 207.3 | R30: 172 | S30: 206.4
A31: 26 | B31: 214.6 | C31: 75 | D31: 177.3 | E31: =+E30+1 -> 124 | F31: 206.5 | G31: 173 | H31: 183.6 | L31: 26 | M31: 214.6 | N31: 75 | O31: 177.3 | P31: =+P30+1 -> 124 | Q31: 206.5 | R31: 173 | S31: 183.6
A32: 27 | B32: 214.7 | C32: 76 | D32: 212.1 | E32: =+E31+1 -> 125 | F32: 169.1 | G32: 174 | H32: 203.7 | L32: 27 | M32: 214.7 | N32: 76 | O32: 212.1 | P32: =+P31+1 -> 125 | Q32: 169.1 | R32: 174 | S32: 203.7
A33: 28 | B33: 212.8 | C33: 77 | D33: 211 | E33: =+E32+1 -> 126 | F33: 209.6 | G33: 175 | H33: 212.2 | L33: 28 | M33: 212.8 | N33: 77 | O33: 211 | P33: =+P32+1 -> 126 | Q33: 209.6 | R33: 175 | S33: 212.2
A34: 29 | B34: 209.8 | C34: 78 | D34: 207.5 | E34: =+E33+1 -> 127 | F34: 194.9 | G34: 176 | H34: 208.4 | L34: 29 | M34: 209.8 | N34: 78 | O34: 207.5 | P34: =+P33+1 -> 127 | Q34: 194.9 | R34: 176 | S34: 208.4
A35: 30 | B35: 189.4 | C35: 79 | D35: 206.6 | E35: =+E34+1 -> 128 | F35: 212.3 | G35: 177 | H35: 174.1 | L35: 30 | M35: 189.4 | N35: 79 | O35: 206.6 | P35: =+P34+1 -> 128 | Q35: 212.3 | R35: 177 | S35: 174.1
A36: 31 | B36: 207.5 | C36: 80 | D36: 180.6 | E36: =+E35+1 -> 129 | F36: 203.9 | G36: 178 | H36: 215.2 | L36: 31 | M36: 207.5 | N36: 80 | O36: 180.6 | P36: =+P35+1 -> 129 | Q36: 203.9 | R36: 178 | S36: 215.2
A37: 32 | B37: 196 | C37: 81 | D37: 207.9 | E37: =+E36+1 -> 130 | F37: 181.8 | G37: 179 | H37: 211.1 | L37: 32 | M37: 196 | N37: 81 | O37: 207.9 | P37: =+P36+1 -> 130 | Q37: 181.8 | R37: 179 | S37: 211.1
A38: 33 | B38: 209.8 | C38: 82 | D38: 183.4 | E38: =+E37+1 -> 131 | F38: 209.6 | G38: 180 | H38: 183.7 | L38: 33 | M38: 209.8 | N38: 82 | O38: 183.4 | P38: =+P37+1 -> 131 | Q38: 209.6 | R38: 180 | S38: 183.7
A39: 34 | B39: 160 | C39: 83 | D39: 208.4 | E39: =+E38+1 -> 132 | F39: 206 | G39: 181 | H39: 202.9 | L39: 34 | M39: 160 | N39: 83 | O39: 208.4 | P39: =+P38+1 -> 132 | Q39: 206 | R39: 181 | S39: 202.9
A40: 35 | B40: 209 | C40: 84 | D40: 212.7 | E40: =+E39+1 -> 133 | F40: 186.1 | G40: 182 | H40: 182.6 | L40: 35 | M40: 209 | N40: 84 | O40: 212.7 | P40: =+P39+1 -> 133 | Q40: 186.1 | R40: 182 | S40: 182.6
A41: 36 | B41: 197.6 | C41: 85 | D41: 186.9 | E41: =+E40+1 -> 134 | F41: 215.3 | G41: 183 | H41: 207 | L41: 36 | M41: 197.6 | N41: 85 | O41: 186.9 | P41: =+P40+1 -> 134 | Q41: 215.3 | R41: 183 | S41: 207
... A54: 49 | B54: 209.3 | C54: 98 | D54: 213.1 | E54: =+E53+1 -> 147 | F54: 199.9 | G54: 196 | H54: 204.8 | L54: 49 | M54: 209.3 | N54: 98 | O54: 213.1 | P54: =+P53+1 -> 147 | Q54: 199.9 | R54: 196 | S54: 204.8
B55: =SUM(B6:B54) -> 9905.73 | D55: =SUM(D6:D54) -> 9909 | F55: =SUM(F6:F54) -> 9713.1 | H55: =SUM(H6:H54) -> 9671.3 | J55: =SUM(J6:J54) -> 4663.5 | M55: =SUM(M6:M54) -> 9905.73 | O55: =SUM(O6:O54) -> 9909 | Q55: =SUM(Q6:Q54) -> 9713.1 | S55: =SUM(S6:S54) -> 9671.3 | U55: =SUM(U6:U54) -> 4663.5
A56: Итого кип | B56: =COUNT(B6:B54,D6:D54,F6:F54,H6:H54,J6:J54) -> 220 | C56: Масса брутто | E56: =B55+D55+F55+H55+J55 -> 43862.63 | F56: Тары | G56: =B56*2.2 -> 484 | H56: Масса нетто | J56: =E56-G56 -> 43378.63 | L56: Итого кип | M56: =COUNT(M6:M54,O6:O54,Q6:Q54,S6:S54,U6:U54) -> 220 | N56: Масса брутто | P56: =M55+O55+Q55+S55+U55 -> 43862.63 | Q56: Тары | R56: =M56*2.2 -> 484 | S56: Масса нетто | U56: =P56-R56 -> 43378.63
A57: Лаборант: | L57: Лаборант:
F59: Тара | G59: 2.2 | Q59: Тара | R59: 2.2

Sheet 230
A1: Акт покипного отвеса | L1: Акт покипного отвеса | W1: Акт покипного отвеса | AH1: Акт покипного отвеса
A2: Лаборатория: хлопзавод при ООО "Navbahor Tekstil" | L2: Лаборатория: хлопзавод при ООО "Navbahor Tekstil" | W2: Лаборатория: хлопзавод при ООО "Navbahor Tekstil" | AH2: Лаборатория: хлопзавод при ООО "Navbahor Tekstil"
A3: Марка № | B3: 230 | I3: Корхона олди | L3: Марка № | M3: 230 | T3: Корхона олди | W3: Марка № | X3: 230 | AE3: Корхона олди | AH3: Марка № | AI3: 230 | AP3: Корхона олди
I4: Жами | T4: 1 яхши | AE4: 1 урта | AP4: 1 оддий
A5: № | B5: Масса | C5: № | D5: Масса | E5: № | F5: Масса | G5: № | H5: Масса | I5: № | J5: Масса | L5: № | M5: Масса | N5: № | O5: Масса | P5: № | Q5: Масса | R5: № | S5: Масса | T5: № | U5: Масса | W5: № | X5: Масса | Y5: № | Z5: Масса | AA5: № | AB5: Масса | AC5: № | AD5: Масса | AE5: № | AF5: Масса | AH5: № | AI5: Масса | AJ5: № | AK5: Масса | AL5: № | AM5: Масса | AN5: № | AO5: Масса | AP5: № | AQ5: Масса
A6: 1 | B6: 216.8 | C6: 50 | D6: 199 | E6: 99 | F6: 211.4 | G6: 148 | H6: 206.7 | I6: 197 | J6: 202.4 | L6: 1 | N6: 50 | P6: 99 | Q6: 211.4 | R6: 148 | T6: 197 | W6: 1 | Y6: 50 | Z6: 199 | AA6: 99 | AC6: 148 | AD6: 206.7 | AE6: 197 | AF6: 202.4 | AH6: 1 | AI6: 216.8 | AJ6: 50 | AL6: 99 | AN6: 148 | AP6: 197
A7: 2 | B7: 211.8 | C7: 51 | D7: 209.8 | E7: 100 | F7: 204.2 | G7: 149 | H7: 206.3 | I7: 198 | J7: 207.3 | L7: 2 | N7: 51 | O7: 209.8 | P7: 100 | Q7: 204.2 | R7: 149 | T7: 198 | W7: 2 | Y7: 51 | AA7: 100 | AC7: 149 | AD7: 206.3 | AE7: 198 | AF7: 207.3 | AH7: 2 | AI7: 211.8 | AJ7: 51 | AL7: 100 | AN7: 149 | AP7: 198
A8: 3 | B8: 214.6 | C8: 52 | D8: 202.1 | E8: =+E7+1 -> 101 | F8: 206.7 | G8: 150 | H8: 206 | I8: 199 | J8: 209.8 | L8: 3 | N8: 52 | O8: 202.1 | P8: =+P7+1 -> 101 | Q8: 206.7 | R8: 150 | T8: 199 | W8: 3 | Y8: 52 | AA8: =+AA7+1 -> 101 | AC8: 150 | AD8: 206 | AE8: 199 | AF8: 209.8 | AH8: 3 | AI8: 214.6 | AJ8: 52 | AL8: =+AL7+1 -> 101 | AN8: 150 | AP8: 199
A9: 4 | B9: 210 | C9: 53 | D9: 191.1 | E9: =+E8+1 -> 102 | F9: 215.8 | G9: 151 | H9: 171.3 | I9: 200 | J9: 177 | L9: 4 | N9: 53 | O9: 191.1 | P9: =+P8+1 -> 102 | Q9: 215.8 | R9: 151 | T9: 200 | W9: 4 | Y9: 53 | AA9: =+AA8+1 -> 102 | AC9: 151 | AD9: 171.3 | AE9: 200 | AF9: 177 | AH9: 4 | AI9: 210 | AJ9: 53 | AL9: =+AL8+1 -> 102 | AN9: 151 | AP9: 200
A10: 5 | B10: 215.1 | C10: 54 | D10: 193.8 | E10: =+E9+1 -> 103 | F10: 210.7 | G10: 152 | H10: 209.9 | I10: 201 | J10: 207.9 | L10: 5 | N10: 54 | O10: 193.8 | P10: =+P9+1 -> 103 | Q10: 210.7 | R10: 152 | T10: 201 | W10: 5 | Y10: 54 | AA10: =+AA9+1 -> 103 | AC10: 152 | AD10: 209.9 | AE10: 201 | AF10: 207.9 | AH10: 5 | AI10: 215.1 | AJ10: 54 | AL10: =+AL9+1 -> 103 | AN10: 152 | AP10: 201
A11: 6 | B11: 210.1 | C11: 55 | D11: 208.4 | E11: =+E10+1 -> 104 | F11: 209.2 | G11: 153 | H11: 211.2 | I11: 202 | J11: 211.1 | L11: 6 | N11: 55 | O11: 208.4 | P11: =+P10+1 -> 104 | Q11: 209.2 | R11: 153 | T11: 202 | W11: 6 | Y11: 55 | AA11: =+AA10+1 -> 104 | AC11: 153 | AD11: 211.2 | AE11: 202 | AF11: 211.1 | AH11: 6 | AI11: 210.1 | AJ11: 55 | AL11: =+AL10+1 -> 104 | AN11: 153 | AP11: 202
A12: 7 | B12: 202.9 | C12: 56 | D12: 205.9 | E12: =+E11+1 -> 105 | F12: 212.2 | G12: 154 | H12: 182.5 | I12: 203 | J12: 177.3 | L12: 7 | N12: 56 | O12: 205.9 | P12: =+P11+1 -> 105 | Q12: 212.2 | R12: 154 | T12: 203 | W12: 7 | Y12: 56 | AA12: =+AA11+1 -> 105 | AC12: 154 | AD12: 182.5 | AE12: 203 | AF12: 177.3 | AH12: 7 | AI12: 202.9 | AJ12: 56 | AL12: =+AL11+1 -> 105 | AN12: 154 | AP12: 203
